<?xml version="1.0" encoding="UTF-8"?>
<testng-results skipped="1" failed="1" total="4" passed="2">
  <reporter-output>
  </reporter-output>
  <suite name="Default suite" duration-ms="93" started-at="2019-05-31T04:30:26Z" finished-at="2019-05-31T04:30:26Z">
    <groups>
    </groups>
    <test name="Default test" duration-ms="93" started-at="2019-05-31T04:30:26Z" finished-at="2019-05-31T04:30:26Z">
      <class name="DemoTestng.NewTest">
        <test-method status="PASS" signature="D()[pri:1, instance:DemoTestng.NewTest@61a485d2]" name="D" duration-ms="15" started-at="2019-05-31T10:00:26Z" finished-at="2019-05-31T10:00:26Z">
          <reporter-output>
          </reporter-output>
        </test-method> <!-- D -->
        <test-method status="FAIL" signature="A()[pri:2, instance:DemoTestng.NewTest@61a485d2]" name="A" duration-ms="7" started-at="2019-05-31T10:00:26Z" finished-at="2019-05-31T10:00:26Z">
          <exception class="java.lang.AssertionError">
            <message>
              <![CDATA[expected [Ghouse] but found [vinay]]]>
            </message>
            <full-stacktrace>
              <![CDATA[java.lang.AssertionError: expected [Ghouse] but found [vinay]
	at org.testng.Assert.fail(Assert.java:94)
	at org.testng.Assert.failNotEquals(Assert.java:513)
	at org.testng.Assert.assertEqualsImpl(Assert.java:135)
	at org.testng.Assert.assertEquals(Assert.java:116)
	at org.testng.Assert.assertEquals(Assert.java:190)
	at org.testng.Assert.assertEquals(Assert.java:200)
	at DemoTestng.NewTest.A(NewTest.java:10)
	at sun.reflect.NativeMethodAccessorImpl.invoke0(Native Method)
	at sun.reflect.NativeMethodAccessorImpl.invoke(Unknown Source)
	at sun.reflect.DelegatingMethodAccessorImpl.invoke(Unknown Source)
	at java.lang.reflect.Method.invoke(Unknown Source)
	at org.testng.internal.MethodInvocationHelper.invokeMethod(MethodInvocationHelper.java:86)
	at org.testng.internal.Invoker.invokeMethod(Invoker.java:643)
	at org.testng.internal.Invoker.invokeTestMethod(Invoker.java:820)
	at org.testng.internal.Invoker.invokeTestMethods(Invoker.java:1128)
	at org.testng.internal.TestMethodWorker.invokeTestMethods(TestMethodWorker.java:129)
	at org.testng.internal.TestMethodWorker.run(TestMethodWorker.java:112)
	at org.testng.TestRunner.privateRun(TestRunner.java:782)
	at org.testng.TestRunner.run(TestRunner.java:632)
	at org.testng.SuiteRunner.runTest(SuiteRunner.java:366)
	at org.testng.SuiteRunner.runSequentially(SuiteRunner.java:361)
	at org.testng.SuiteRunner.privateRun(SuiteRunner.java:319)
	at org.testng.SuiteRunner.run(SuiteRunner.java:268)
	at org.testng.SuiteRunnerWorker.runSuite(SuiteRunnerWorker.java:52)
	at org.testng.SuiteRunnerWorker.run(SuiteRunnerWorker.java:86)
	at org.testng.TestNG.runSuitesSequentially(TestNG.java:1244)
	at org.testng.TestNG.runSuitesLocally(TestNG.java:1169)
	at org.testng.TestNG.run(TestNG.java:1064)
	at org.testng.remote.AbstractRemoteTestNG.run(AbstractRemoteTestNG.java:114)
	at org.testng.remote.RemoteTestNG.initAndRun(RemoteTestNG.java:251)
	at org.testng.remote.RemoteTestNG.main(RemoteTestNG.java:77)
]]>
            </full-stacktrace>
          </exception> <!-- java.lang.AssertionError -->
          <reporter-output>
          </reporter-output>
        </test-method> <!-- A -->
        <test-method status="PASS" signature="C()[pri:4, instance:DemoTestng.NewTest@61a485d2]" name="C" duration-ms="7" started-at="2019-05-31T10:00:26Z" finished-at="2019-05-31T10:00:26Z">
          <reporter-output>
          </reporter-output>
        </test-method> <!-- C -->
        <test-method status="SKIP" signature="B()[pri:3, instance:DemoTestng.NewTest@61a485d2]" name="B" duration-ms="0" started-at="2019-05-31T10:00:26Z" depends-on-methods="DemoTestng.NewTest.A" finished-at="2019-05-31T10:00:26Z">
          <exception class="java.lang.Throwable">
            <message>
              <![CDATA[Method NewTest.B()[pri:3, instance:DemoTestng.NewTest@61a485d2] depends on not successfully finished methods]]>
            </message>
            <full-stacktrace>
              <![CDATA[java.lang.Throwable: Method NewTest.B()[pri:3, instance:DemoTestng.NewTest@61a485d2] depends on not successfully finished methods
	at org.testng.internal.Invoker.invokeTestMethods(Invoker.java:1037)
	at org.testng.internal.TestMethodWorker.invokeTestMethods(TestMethodWorker.java:129)
	at org.testng.internal.TestMethodWorker.run(TestMethodWorker.java:112)
	at org.testng.TestRunner.privateRun(TestRunner.java:782)
	at org.testng.TestRunner.run(TestRunner.java:632)
	at org.testng.SuiteRunner.runTest(SuiteRunner.java:366)
	at org.testng.SuiteRunner.runSequentially(SuiteRunner.java:361)
	at org.testng.SuiteRunner.privateRun(SuiteRunner.java:319)
	at org.testng.SuiteRunner.run(SuiteRunner.java:268)
	at org.testng.SuiteRunnerWorker.runSuite(SuiteRunnerWorker.java:52)
	at org.testng.SuiteRunnerWorker.run(SuiteRunnerWorker.java:86)
	at org.testng.TestNG.runSuitesSequentially(TestNG.java:1244)
	at org.testng.TestNG.runSuitesLocally(TestNG.java:1169)
	at org.testng.TestNG.run(TestNG.java:1064)
	at org.testng.remote.AbstractRemoteTestNG.run(AbstractRemoteTestNG.java:114)
	at org.testng.remote.RemoteTestNG.initAndRun(RemoteTestNG.java:251)
	at org.testng.remote.RemoteTestNG.main(RemoteTestNG.java:77)
]]>
            </full-stacktrace>
          </exception> <!-- java.lang.Throwable -->
          <reporter-output>
          </reporter-output>
        </test-method> <!-- B -->
      </class> <!-- DemoTestng.NewTest -->
    </test> <!-- Default test -->
  </suite> <!-- Default suite -->
</testng-results>
